Workbook

Sheet MENU

Sheet Problem 1
B13: FACTS
B14: ISIN | C14: DE0001030559
B15: Daycount standard | C15: ACT/ACT ICMA
B16: Coupon payment frequency | C16: Annual
B18: DATA
B19: Real coupon rate | C19: 0.005
B20: Clean Price (2015) | C20: 101.78
B21: Face Value | C21: 100
B22: Trade date | C22: 46100
B23: Settlement date (T2) | C23: =IF(WEEKDAY(C22,2)=5,C22+3,IF(WEEKDAY(C22,2)=4,C22+4,C22+2)) -> 46104
B24: Previous distribution date | C24: =IF(DATE(YEAR(C23),4,15)<=C23,DATE(YEAR(C23),4,15),DATE(YEAR(C23)-1,4,15)) -> 45762
B25: Accrual period (days) | C25: =IF(EDATE(C24,12)=C23,0,_xlfn.DAYS(C23,C24)) -> 342
B26: Inflation coefficient (settlement date) | C26: =_xlfn.XLOOKUP(C23,coefficient!A:A,coefficient!B:B,"") -> 1.29437
B28: OUTPUT - REAL (2015)
B29: Clean Price | C29: =C20 -> 101.78
B30: plus: Accrued Interest
B31: Dirty Price
B33: OUTPUT - NOMINAL (2026)
B34: Clean Price | C34: =C29*$C$26 -> 131.74098
B35: plus: Accrued Interest
B36: Dirty Price

Sheet Solution 1
B13: FACTS
B14: ISIN | C14: DE0001030559
B15: Daycount standard | C15: ACT/ACT ICMA
B16: Coupon payment frequency | C16: Annual
B18: DATA
B19: Real coupon rate | C19: 0.005
B20: Clean Price (2015) | C20: 101.78
B21: Face Value | C21: 100
B22: Trade date | C22: 46100
B23: Settlement date (T2) | C23: =IF(WEEKDAY(C22,2)=5,C22+3,IF(WEEKDAY(C22,2)=4,C22+4,C22+2)) -> 46104
B24: Previous distribution date | C24: =IF(DATE(YEAR(C23),4,15)<=C23,DATE(YEAR(C23),4,15),DATE(YEAR(C23)-1,4,15)) -> 45762
B25: Accrual period (days) | C25: =IF(EDATE(C24,12)=C23,0,_xlfn.DAYS(C23,C24)) -> 342
B26: Inflation coefficient (settlement date) | C26: =_xlfn.XLOOKUP(C23,coefficient!A:A,coefficient!B:B,"") -> 1.29437
B28: OUTPUT - REAL (2015)
B29: Clean Price | C29: =C20 -> 101.78
B30: plus: Accrued Interest | C30: =C21*C19*(C25/_xlfn.DAYS(EDATE(C24,12),C24)) -> 0.46849315
B31: Dirty Price | C31: =C29+C30 -> 102.24849
B33: OUTPUT - NOMINAL (2026)
B34: Clean Price | C34: =C29*$C$26 -> 131.74098
B35: plus: Accrued Interest | C35: =C30*$C$26 -> 0.60640348
B36: Dirty Price | C36: =C31*$C$26 -> 132.34738
B43: BACKTEST

Sheet coefficient
A1: Date | B1: Coefficient
A2: 46082 | B2: 1.29987
A3: 46083 | B3: 1.29962
A4: 46084 | B4: 1.29937
A5: 46085 | B5: 1.29912
A6: 46086 | B6: 1.29887
A7: 46087 | B7: 1.29862
A8: 46088 | B8: 1.29837
A9: 46089 | B9: 1.29812
A10: 46090 | B10: 1.29787
A11: 46091 | B11: 1.29762
A12: 46092 | B12: 1.29737
A13: 46093 | B13: 1.29712
... A63: 46143 | B63: 1.30052

Sheet Problem 2
B12: FACTS
B13: ISIN | C13: DE0001030559
B14: Daycount standard | C14: ACT/ACT ICMA
B15: Coupon payment frequency | C15: Annual
B17: DATA
B18: Real yield-to-maturity | C18: 0.000612
B19: Real coupon rate | C19: 0.005
B20: Face Value | C20: 100
B21: Trade date | C21: 46100
B22: Settlement date (T2) | C22: =IF(WEEKDAY(C21,2)=5,C21+3,IF(WEEKDAY(C21,2)=4,C21+4,C21+2)) -> 46104
B23: Last distribution date | C23: =IF(DATE(YEAR(C22),4,15)<=C22,DATE(YEAR(C22),4,15),DATE(YEAR(C22)-1,4,15)) -> 45762
B24: Upcoming distribution date | C24: =EDATE(C23,12) -> 46127
B25: Maturity date | C25: 47588
B26: Accrual Period (days) | C26: =IF(EDATE(C23,12)=C22,0,_xlfn.DAYS(C22,C23)) -> 342
B27: Inflation coefficient (settlement date) | C27: =_xlfn.XLOOKUP(C22,coefficient!A:A,coefficient!B:B,"") -> 1.29437
B30: CASH FLOW SCHEDULE - REAL 2014
B32: Date | C32: 46127 | D32: 46492 | E32: 46858 | F32: 47223 | G32: 47588
B33: Coupon
B34: Principal
B35: Total Payment
B36: Day count till next coupon
B37: Day count factor
B38: Discount factor
B39: Present Value
B41: Dirty Price (real)
B42: Less: Accrued Interest (real)
B43: Clean Price (real)
B47: CASH FLOW SCHEDULE - REAL 2026
B49: Date | C49: 46127 | D49: 46492 | E49: 46858 | F49: 47223 | G49: 47588
B50: Coupon
B51: Principal
B52: Total Payment
B53: Day count till next coupon
B54: Day count factor
B55: Discount factor
B56: Present Value
B58: Dirty Price (real)
B59: Less: Accrued Interest (real)
B60: Clean Price (real)

Sheet Solution 2
B17: FACTS
B18: ISIN | C18: DE0001030559
B19: Daycount standard | C19: ACT/ACT ICMA
B20: Coupon payment frequency | C20: Annual
B22: DATA
B23: Real yield-to-maturity | C23: 0.000612
B24: Real coupon rate | C24: 0.005
B25: Face Value | C25: 100
B26: Trade date | C26: 46100
B27: Settlement date (T2) | C27: =IF(WEEKDAY(C26,2)=5,C26+3,IF(WEEKDAY(C26,2)=4,C26+4,C26+2)) -> 46104
B28: Last distribution date | C28: =IF(DATE(YEAR(C27),4,15)<=C27,DATE(YEAR(C27),4,15),DATE(YEAR(C27)-1,4,15)) -> 45762
B29: Upcoming distribution date | C29: =EDATE(C28,12) -> 46127
B30: Maturity date | C30: 47588
B31: Accrual Period (days) | C31: =IF(EDATE(C28,12)=C27,0,_xlfn.DAYS(C27,C28)) -> 342
B32: Inflation coefficient (settlement date) | C32: =_xlfn.XLOOKUP(C27,coefficient!A:A,coefficient!B:B,"") -> 1.29437
B35: CASH FLOW SCHEDULE - REAL 2014
B37: Date | C37: 46127 | D37: 46492 | E37: 46858 | F37: 47223 | G37: 47588
B38: Coupon | C38: =$C$24*$C$25 -> 0.5 | D38: =$C$24*$C$25 -> 0.5 | E38: =$C$24*$C$25 -> 0.5 | F38: =$C$24*$C$25 -> 0.5 | G38: =$C$24*$C$25 -> 0.5
B39: Principal | G39: =C25 -> 100
B40: Total Payment | C40: =SUM(C38:C39) -> 0.5 | D40: =SUM(D38:D39) -> 0.5 | E40: =SUM(E38:E39) -> 0.5 | F40: =SUM(F38:F39) -> 0.5 | G40: =SUM(G38:G39) -> 100.5
B41: Day count till next coupon | C41: =_xlfn.DAYS(C37,C27) -> 23 | D41: =_xlfn.DAYS(D37,C37) -> 365 | E41: =_xlfn.DAYS(E37,D37) -> 366 | F41: =_xlfn.DAYS(F37,E37) -> 365 | G41: =_xlfn.DAYS(G37,F37) -> 365
B42: Day count factor | C42: =C41/_xlfn.DAYS(C37,C28) -> 0.063013699 | D42: =C42+D41/D41 -> 1.0630137 | E42: =D42+E41/E41 -> 2.0630137 | F42: =E42+F41/F41 -> 3.0630137 | G42: =F42+G41/G41 -> 4.0630137
B43: Discount factor | C43: =1/(1+$C$23)^(C42) -> 0.99996145 | D43: =1/(1+$C$23)^(D42) -> 0.99934985 | E43: =1/(1+$C$23)^(E42) -> 0.99873862 | F43: =1/(1+$C$23)^(F42) -> 0.99812776 | G43: =1/(1+$C$23)^(G42) -> 0.99751728
B44: Present Value | C44: =C40*C43 -> 0.49998072 | D44: =D40*D43 -> 0.49967492 | E44: =E40*E43 -> 0.49936931 | F44: =F40*F43 -> 0.49906388 | G44: =G40*G43 -> 100.25049
B46: Dirty Price (real) | C46: =SUM(C44:G44) -> 102.24858
B47: Less: Accrued Interest (real) | C47: =C25*C24*(C31/_xlfn.DAYS(EDATE(C28,12),C28)) -> 0.46849315
B48: Clean Price (real) | C48: =C46-C47 -> 101.78008
B52: CASH FLOW SCHEDULE - REAL 2026
B54: Date | C54: 46127 | D54: 46492 | E54: 46858 | F54: 47223 | G54: 47588
B55: Coupon | C55: =$C$24*$C$25 -> 0.5 | D55: =$C$24*$C$25 -> 0.5 | E55: =$C$24*$C$25 -> 0.5 | F55: =$C$24*$C$25 -> 0.5 | G55: =$C$24*$C$25 -> 0.5
B56: Principal | G56: =$C$25 -> 100
B57: Total Payment | C57: =SUM(C55:C56)*$C$32 -> 0.647185 | D57: =SUM(D55:D56)*$C$32 -> 0.647185 | E57: =SUM(E55:E56)*$C$32 -> 0.647185 | F57: =SUM(F55:F56)*$C$32 -> 0.647185 | G57: =SUM(G55:G56)*$C$32 -> 130.08418
B58: Day count till next coupon | C58: =_xlfn.DAYS(C54,C27) -> 23 | D58: =_xlfn.DAYS(D54,C54) -> 365 | E58: =_xlfn.DAYS(E54,D54) -> 366 | F58: =_xlfn.DAYS(F54,E54) -> 365 | G58: =_xlfn.DAYS(G54,F54) -> 365
B59: Day count factor | C59: =C58/_xlfn.DAYS(C54,C28) -> 0.063013699 | D59: =C59+D58/D58 -> 1.0630137 | E59: =D59+E58/E58 -> 2.0630137 | F59: =E59+F58/F58 -> 3.0630137 | G59: =F59+G58/G58 -> 4.0630137
B60: Discount factor | C60: =1/(1+$C$23)^(C59) -> 0.99996145 | D60: =1/(1+$C$23)^(D59) -> 0.99934985 | E60: =1/(1+$C$23)^(E59) -> 0.99873862 | F60: =1/(1+$C$23)^(F59) -> 0.99812776 | G60: =1/(1+$C$23)^(G59) -> 0.99751728
B61: Present Value | C61: =C57*C60 -> 0.64716005 | D61: =D57*D60 -> 0.64676423 | E61: =E57*E60 -> 0.64636865 | F61: =F57*F60 -> 0.64597332 | G61: =G57*G60 -> 129.76122
B63: Dirty Price (real) | C63: =SUM(C61:G61) -> 132.34749
B64: Less: Accrued Interest (real) | C64: =C32*C25*C24*(C31/_xlfn.DAYS(EDATE(C28,12),C28)) -> 0.60640348
B65: Clean Price (real) | C65: =C63-C64 -> 131.74109
B69: ASSUMPTIONS
...

Sheet Problem 3
B14: FACTS - NOMINAL | G14: FACTS - REAL
B15: ISIN | C15: DE000BU25042 | G15: ISIN | H15: DE0001030559
B16: Nominal coupon rate | C16: 0.00024 | G16: Real coupon rate | H16: 0.005
B17: Nominal yield-to-maturity | C17: 0.026088 | G17: Real yield-to-maturity | H17: 0.000612
B18: Today | C18: =TODAY() -> 46247 | G18: Today | H18: =TODAY() -> 46247
B19: Maturity date | C19: 47591 | G19: Maturity date | H19: 47588
B20: Residual maturity | C20: =YEARFRAC(C19,C18,1) -> 3.6801752 | G20: Residual maturity | H20: =YEARFRAC(H19,H18,1) -> 3.6719606
B21: Coupon payment frequency | C21: Annual | G21: Coupon payment frequency | H21: Annual
D27: Expected inflation I
D29: Expected inflation II

Sheet Solution 3
B14: FACTS - NOMINAL | G14: FACTS - REAL
B15: ISIN | C15: DE000BU25042 | G15: ISIN | H15: DE0001030559
B16: Nominal coupon rate | C16: 0.00024 | G16: Real coupon rate | H16: 0.005
B17: Nominal yield-to-maturity | C17: 0.026088 | G17: Real yield-to-maturity | H17: 0.000612
B18: Today | C18: =TODAY() -> 46247 | G18: Today | H18: =TODAY() -> 46247
B19: Maturity date | C19: 47591 | G19: Maturity date | H19: 47588
B20: Residual maturity | C20: =YEARFRAC(C19,C18,1) -> 3.6801752 | G20: Residual maturity | H20: =YEARFRAC(H19,H18,1) -> 3.6719606
B21: Coupon payment frequency | C21: Annual | G21: Coupon payment frequency | H21: Annual
D27: Expected inflation I | F27: =(1+C17)/(1+H17)-1 -> 0.025460418
D29: Expected inflation II | F29: =C17-H17 -> 0.025476
B35: BACKTEST

Sheet Problem 4
B12: FACTS
B13: ISIN | C13: DE0001030583
B14: Daycount standard | C14: ACT/ACT ICMA
B15: Coupon payment frequency | C15: Annual
B17: DATA
B18: Real yield-to-maturity | C18: 0.006338
B19: Real coupon rate | C19: 0.001
B20: Liability | C20: 10000
B21: Trade date | C21: 46107
B22: Settlement date (T2) | C22: =IF(WEEKDAY(C21,2)=5,C21+3,IF(WEEKDAY(C21,2)=4,C21+4,C21+2)) -> 46111
B23: Last distribution date | C23: =IF(DATE(YEAR(C22),4,15)<=C22,DATE(YEAR(C22),4,15),DATE(YEAR(C22)-1,4,15)) -> 45762
B24: Upcoming distribution date | C24: =EDATE(C23,12) -> 46127
B25: Maturity date | C25: 48684
B26: Accrual Period (days) | C26: =IF(EDATE(C23,12)=C22,0,_xlfn.DAYS(C22,C23)) -> 349
B27: Inflation coefficient (settlement date) | C27: =_xlfn.XLOOKUP(C22,coefficient2!A:A,coefficient2!B:B,"") -> 1.22681
B31: CASH FLOW SCHEDULE - REAL 2026
B33: Date | C33: 46127 | D33: 46492 | E33: 46858 | F33: 47223 | G33: 47588 | H33: 47953 | I33: 48319 | J33: 48684
B34: Total Payment | C34: 0 | D34: 0 | E34: 0 | F34: 0 | G34: 0 | H34: 0 | I34: 0 | J34: =C20 -> 10000
B35: Day count till next coupon
B36: Day count factor
B37: Discount factor
B38: Present Value
B40: Dirty Price (real)

Sheet Solution 4
B12: FACTS
B13: ISIN | C13: DE0001030583
B14: Daycount standard | C14: ACT/ACT ICMA
B15: Coupon payment frequency | C15: Annual
B17: DATA
B18: Real yield-to-maturity | C18: 0.006338
B19: Real coupon rate | C19: 0.001
B20: Liability | C20: 10000
B21: Trade date | C21: 46107
B22: Settlement date (T2) | C22: =IF(WEEKDAY(C21,2)=5,C21+3,IF(WEEKDAY(C21,2)=4,C21+4,C21+2)) -> 46111
B23: Last distribution date | C23: =IF(DATE(YEAR(C22),4,15)<=C22,DATE(YEAR(C22),4,15),DATE(YEAR(C22)-1,4,15)) -> 45762
B24: Upcoming distribution date | C24: =EDATE(C23,12) -> 46127
B25: Maturity date | C25: 48684
B26: Accrual Period (days) | C26: =IF(EDATE(C23,12)=C22,0,_xlfn.DAYS(C22,C23)) -> 349
B27: Inflation coefficient (settlement date) | C27: =_xlfn.XLOOKUP(C22,coefficient2!A:A,coefficient2!B:B,"") -> 1.22681
B31: CASH FLOW SCHEDULE - REAL 2026
B33: Date | C33: 46127 | D33: 46492 | E33: 46858 | F33: 47223 | G33: 47588 | H33: 47953 | I33: 48319 | J33: 48684
B34: Total Payment | C34: 0 | D34: 0 | E34: 0 | F34: 0 | G34: 0 | H34: 0 | I34: 0 | J34: =C20 -> 10000
B35: Day count till next coupon | C35: =_xlfn.DAYS(C33,C22) -> 16 | D35: =_xlfn.DAYS(D33,C33) -> 365 | E35: =_xlfn.DAYS(E33,D33) -> 366 | F35: =_xlfn.DAYS(F33,E33) -> 365 | G35: =_xlfn.DAYS(G33,F33) -> 365 | H35: =_xlfn.DAYS(H33,G33) -> 365 | I35: =_xlfn.DAYS(I33,H33) -> 366 | J35: =_xlfn.DAYS(J33,I33) -> 365
B36: Day count factor | C36: =C35/_xlfn.DAYS(C33,C23) -> 0.043835616 | D36: =C36+D35/D35 -> 1.0438356 | E36: =D36+E35/E35 -> 2.0438356 | F36: =E36+F35/F35 -> 3.0438356 | G36: =F36+G35/G35 -> 4.0438356 | H36: =G36+H35/H35 -> 5.0438356 | I36: =H36+I35/I35 -> 6.0438356 | J36: =I36+J35/J35 -> 7.0438356
B37: Discount factor | C37: =1/(1+$C$18)^(C36) -> 0.99972308 | D37: =1/(1+$C$18)^(D36) -> 0.99342675 | E37: =1/(1+$C$18)^(E36) -> 0.98717006 | F37: =1/(1+$C$18)^(F36) -> 0.98095278 | G37: =1/(1+$C$18)^(G36) -> 0.97477466 | H37: =1/(1+$C$18)^(H36) -> 0.96863545 | I37: =1/(1+$C$18)^(I36) -> 0.9625349 | J37: =1/(1+$C$18)^(J36) -> 0.95647278
B38: Present Value | C38: =C34*C37 -> 0 | D38: =D34*D37 -> 0 | E38: =E34*E37 -> 0 | F38: =F34*F37 -> 0 | G38: =G34*G37 -> 0 | H38: =H34*H37 -> 0 | I38: =I34*I37 -> 0 | J38: =J34*J37 -> 9564.7278
B40: Dirty Price (real) | C40: =SUM(C38:J38) -> 9564.7278

Sheet coefficient2
A1: Date | B1: Coefficient
A2: 46082 | B2: 1.23369
A3: 46083 | B3: 1.23346
A4: 46084 | B4: 1.23322
A5: 46085 | B5: 1.23298
A6: 46086 | B6: 1.23274
A7: 46087 | B7: 1.23251
A8: 46088 | B8: 1.23227
A9: 46089 | B9: 1.23203
A10: 46090 | B10: 1.23179
A11: 46091 | B11: 1.23156
A12: 46092 | B12: 1.23132
A13: 46093 | B13: 1.23108
... A63: 46143 | B63: 1.23431

Sheet Daňová vsuvka

Sheet Bonds €i
A1: ISIN | B1: Issuer | C1: Maturity | D1: Rating Moody's | E1: Rating S&P | F1: YTM
A2: ES00000128S2 | B2: Spain | C2: 46721 | D2: A3 | E2: A+ | F2: YES
A3: ES00000127C8 | B3: Spain | C3: 47817 | D3: A3 | E3: A+ | F3: YES
A4: ES0000012C12 | B4: Spain | C4: 48913 | D4: A3 | E4: A+ | F4: YES
A5: ES0000012O18 | B5: Spain | C5: 50009 | D5: A3 | E5: A+ | F5: YES
A6: ES0000012M69 | B6: Spain | C6: 51104 | D6: A3 | E6: A+ | F6: YES
A7: ES0000012F19 | B7: Spain | C7: 54392 | D7: A3 | E7: A+ | F7: NO
A8: ES0000012F27 | B8: Spain | C8: 54757 | D8: A3 | E8: A+ | F8: NO
A9: ES0000012F35 | B9: Spain | C9: 55122 | D9: A3 | E9: A+ | F9: NO
A10: IT0005657348 | B10: Italy | C10: 48075 | D10: Baa2 | E10: BBB+ | F10: NO
A11: IT0005647273 | B11: Italy | C11: 57115 | D11: Baa2 | E11: BBB+ | F11: NO
A12: IT0005588881 | B12: Italy | C12: 49810 | D12: Baa2 | E12: BBB+ | F12: NO
A13: IT0005547812 | B13: Italy | C13: 50905 | D13: Baa2 | E13: BBB+ | F13: NO
... A40: DE0001030559 | B40: Germany | C40: 47588 | D40: Aaa | E40: AAA | F40: YES
